log/output_300_2021_CNN_gpu2.log
wandb: W&B API key is configured. Use `wandb login --relogin` to force relogin
GPU device ID: 2
newdata/300_2021.npy
0
wandb: wandb version 0.17.9 is available!  To upgrade, please run:
wandb:  $ pip install wandb --upgrade
wandb: Tracking run with wandb version 0.12.17
wandb: Run data is saved locally in /home/qingyi/GPU20/DeepLOB/wandb/run-20240907_160535-1jxfobht
wandb: Run `wandb offline` to turn off syncing.
wandb: Syncing run CNN
wandb: ⭐️ View project at https://wandb.ai/pqythu/futures300
wandb: 🚀 View run at https://wandb.ai/pqythu/futures300/runs/1jxfobht
2024-09-07 16:05:46.552885: I tensorflow/core/platform/cpu_feature_guard.cc:193] This TensorFlow binary is optimized with oneAPI Deep Neural Network Library (oneDNN) to use the following CPU instructions in performance-critical operations:  AVX2 FMA
To enable them in other operations, rebuild TensorFlow with the appropriate compiler flags.
Model(
  (conv1): Conv1d(10, 64, kernel_size=(3,), stride=(1,), padding=(1,))
  (conv2): Conv1d(64, 64, kernel_size=(3,), stride=(1,), padding=(1,))
  (pool): MaxPool1d(kernel_size=2, stride=2, padding=0, dilation=1, ceil_mode=False)
  (fc): Linear(in_features=512, out_features=5, bias=True)
)
number of parameters: 16901
Training start
epoch  1 | time used:  2.47s | train_loss 1.471 | valid loss 1.521 | valid acc 0.425 | mae 1.845 | mse 6.585 | rmse 2.57 | r2 -1.07 | sharp 0.00
epoch  2 | time used:  0.05s | train_loss 1.449 | valid loss 1.521 | valid acc 0.425 | mae 1.845 | mse 6.585 | rmse 2.57 | r2 -1.07 | sharp 0.00
epoch  3 | time used:  0.04s | train_loss 1.469 | valid loss 1.521 | valid acc 0.425 | mae 1.845 | mse 6.585 | rmse 2.57 | r2 -1.07 | sharp 0.00
epoch  4 | time used:  0.04s | train_loss 1.455 | valid loss 1.521 | valid acc 0.425 | mae 1.845 | mse 6.585 | rmse 2.57 | r2 -1.07 | sharp 0.00
epoch  5 | time used:  0.04s | train_loss 1.496 | valid loss 1.521 | valid acc 0.425 | mae 1.845 | mse 6.585 | rmse 2.57 | r2 -1.07 | sharp 0.00
epoch  6 | time used:  0.04s | train_loss 1.451 | valid loss 1.521 | valid acc 0.425 | mae 1.845 | mse 6.585 | rmse 2.57 | r2 -1.07 | sharp 0.00
epoch  7 | time used:  0.04s | train_loss 1.463 | valid loss 1.521 | valid acc 0.425 | mae 1.845 | mse 6.585 | rmse 2.57 | r2 -1.07 | sharp 0.00
epoch  8 | time used:  0.04s | train_loss 1.470 | valid loss 1.528 | valid acc 0.355 | mae 2.155 | mse 7.825 | rmse 2.80 | r2 -1.46 | sharp 2.58
epoch  9 | time used:  0.04s | train_loss 1.535 | valid loss 1.388 | valid acc 0.355 | mae 2.155 | mse 7.825 | rmse 2.80 | r2 -1.46 | sharp 2.58
epoch 10 | time used:  0.04s | train_loss 1.529 | valid loss 1.388 | valid acc 0.355 | mae 2.155 | mse 7.825 | rmse 2.80 | r2 -1.46 | sharp 2.58
saving the model to ./save/2021_300/CNN/checkpoint10.pt
epoch 11 | time used:  0.04s | train_loss 1.507 | valid loss 1.388 | valid acc 0.355 | mae 2.155 | mse 7.825 | rmse 2.80 | r2 -1.46 | sharp 2.58
epoch 12 | time used:  0.04s | train_loss 1.537 | valid loss 1.388 | valid acc 0.355 | mae 2.155 | mse 7.825 | rmse 2.80 | r2 -1.46 | sharp 2.58
epoch 13 | time used:  0.04s | train_loss 1.456 | valid loss 1.521 | valid acc 0.425 | mae 1.845 | mse 6.585 | rmse 2.57 | r2 -1.07 | sharp 0.00
epoch 14 | time used:  0.05s | train_loss 1.457 | valid loss 1.521 | valid acc 0.425 | mae 1.845 | mse 6.585 | rmse 2.57 | r2 -1.07 | sharp 0.00
epoch 15 | time used:  0.05s | train_loss 1.430 | valid loss 1.521 | valid acc 0.425 | mae 1.845 | mse 6.585 | rmse 2.57 | r2 -1.07 | sharp 0.00
epoch 16 | time used:  0.04s | train_loss 1.455 | valid loss 1.521 | valid acc 0.425 | mae 1.845 | mse 6.585 | rmse 2.57 | r2 -1.07 | sharp 0.00
epoch 17 | time used:  0.04s | train_loss 1.481 | valid loss 1.521 | valid acc 0.425 | mae 1.845 | mse 6.585 | rmse 2.57 | r2 -1.07 | sharp 0.00
epoch 18 | time used:  0.04s | train_loss 1.454 | valid loss 1.521 | valid acc 0.425 | mae 1.845 | mse 6.585 | rmse 2.57 | r2 -1.07 | sharp 0.00
epoch 19 | time used:  0.04s | train_loss 1.482 | valid loss 1.521 | valid acc 0.425 | mae 1.845 | mse 6.585 | rmse 2.57 | r2 -1.07 | sharp 0.00
epoch 20 | time used:  0.04s | train_loss 1.473 | valid loss 1.388 | valid acc 0.355 | mae 2.155 | mse 7.825 | rmse 2.80 | r2 -1.46 | sharp 2.58
saving the model to ./save/2021_300/CNN/checkpoint20.pt
epoch 21 | time used:  0.04s | train_loss 1.511 | valid loss 1.388 | valid acc 0.355 | mae 2.155 | mse 7.825 | rmse 2.80 | r2 -1.46 | sharp 2.58
epoch 22 | time used:  0.04s | train_loss 1.468 | valid loss 1.521 | valid acc 0.425 | mae 1.845 | mse 6.585 | rmse 2.57 | r2 -1.07 | sharp 0.00
epoch 23 | time used:  0.03s | train_loss 1.470 | valid loss 1.521 | valid acc 0.425 | mae 1.845 | mse 6.585 | rmse 2.57 | r2 -1.07 | sharp 0.00
epoch 24 | time used:  0.03s | train_loss 1.465 | valid loss 1.521 | valid acc 0.425 | mae 1.845 | mse 6.585 | rmse 2.57 | r2 -1.07 | sharp 0.00
epoch 25 | time used:  0.03s | train_loss 1.448 | valid loss 1.521 | valid acc 0.425 | mae 1.845 | mse 6.585 | rmse 2.57 | r2 -1.07 | sharp 0.00
epoch 26 | time used:  0.03s | train_loss 1.498 | valid loss 1.521 | valid acc 0.425 | mae 1.845 | mse 6.585 | rmse 2.57 | r2 -1.07 | sharp 0.00
epoch 27 | time used:  0.03s | train_loss 1.468 | valid loss 1.521 | valid acc 0.425 | mae 1.845 | mse 6.585 | rmse 2.57 | r2 -1.07 | sharp 0.00
epoch 28 | time used:  0.03s | train_loss 1.437 | valid loss 1.521 | valid acc 0.425 | mae 1.845 | mse 6.585 | rmse 2.57 | r2 -1.07 | sharp 0.00
epoch 29 | time used:  0.03s | train_loss 1.458 | valid loss 1.521 | valid acc 0.425 | mae 1.845 | mse 6.585 | rmse 2.57 | r2 -1.07 | sharp 0.00
epoch 30 | time used:  0.03s | train_loss 1.433 | valid loss 1.521 | valid acc 0.425 | mae 1.845 | mse 6.585 | rmse 2.57 | r2 -1.07 | sharp 0.00
saving the model to ./save/2021_300/CNN/checkpoint30.pt
epoch 31 | time used:  0.03s | train_loss 1.444 | valid loss 1.521 | valid acc 0.425 | mae 1.845 | mse 6.585 | rmse 2.57 | r2 -1.07 | sharp 0.00
epoch 32 | time used:  0.03s | train_loss 1.437 | valid loss 1.521 | valid acc 0.425 | mae 1.845 | mse 6.585 | rmse 2.57 | r2 -1.07 | sharp 0.00
epoch 33 | time used:  0.03s | train_loss 1.443 | valid loss 1.521 | valid acc 0.425 | mae 1.845 | mse 6.585 | rmse 2.57 | r2 -1.07 | sharp 0.00
epoch 34 | time used:  0.03s | train_loss 1.467 | valid loss 1.521 | valid acc 0.425 | mae 1.845 | mse 6.585 | rmse 2.57 | r2 -1.07 | sharp 0.00
epoch 35 | time used:  0.03s | train_loss 1.482 | valid loss 1.521 | valid acc 0.425 | mae 1.845 | mse 6.585 | rmse 2.57 | r2 -1.07 | sharp 0.00
epoch 36 | time used:  0.03s | train_loss 1.465 | valid loss 1.521 | valid acc 0.425 | mae 1.845 | mse 6.585 | rmse 2.57 | r2 -1.07 | sharp 0.00
epoch 37 | time used:  0.03s | train_loss 1.454 | valid loss 1.521 | valid acc 0.425 | mae 1.845 | mse 6.585 | rmse 2.57 | r2 -1.07 | sharp 0.00
epoch 38 | time used:  0.03s | train_loss 1.468 | valid loss 1.521 | valid acc 0.425 | mae 1.845 | mse 6.585 | rmse 2.57 | r2 -1.07 | sharp 0.00
epoch 39 | time used:  0.03s | train_loss 1.451 | valid loss 1.521 | valid acc 0.425 | mae 1.845 | mse 6.585 | rmse 2.57 | r2 -1.07 | sharp 0.00
epoch 40 | time used:  0.03s | train_loss 1.419 | valid loss 1.521 | valid acc 0.425 | mae 1.845 | mse 6.585 | rmse 2.57 | r2 -1.07 | sharp 0.00
saving the model to ./save/2021_300/CNN/checkpoint40.pt
epoch 41 | time used:  0.03s | train_loss 1.464 | valid loss 1.521 | valid acc 0.425 | mae 1.845 | mse 6.585 | rmse 2.57 | r2 -1.07 | sharp 0.00
epoch 42 | time used:  0.03s | train_loss 1.455 | valid loss 1.521 | valid acc 0.425 | mae 1.845 | mse 6.585 | rmse 2.57 | r2 -1.07 | sharp 0.00
epoch 43 | time used:  0.03s | train_loss 1.481 | valid loss 1.521 | valid acc 0.425 | mae 1.845 | mse 6.585 | rmse 2.57 | r2 -1.07 | sharp 0.00
epoch 44 | time used:  0.03s | train_loss 1.456 | valid loss 1.521 | valid acc 0.425 | mae 1.845 | mse 6.585 | rmse 2.57 | r2 -1.07 | sharp 0.00
epoch 45 | time used:  0.03s | train_loss 1.435 | valid loss 1.521 | valid acc 0.425 | mae 1.845 | mse 6.585 | rmse 2.57 | r2 -1.07 | sharp 0.00
